<mujoco model="T1">
  <compiler angle="radian" autolimits="true" />

  <option iterations="3" ls_iterations="5" timestep=".002" integrator="Euler">
    <flag eulerdamp="disable" />
  </option>

  <asset>
    <material name="light_gray" rgba="0.76 0.76 0.76 1" />
    <material name="medium_gray" rgba="0.4 0.4 0.4 1" />

    <mesh file="meshes/Trunk.STL" />
    <mesh file="meshes/H1.STL" />
    <mesh file="meshes/H2.STL" />
    <mesh file="meshes/AL1.STL" />
    <mesh file="meshes/AL2.STL" />
    <mesh file="meshes/AL3.STL" />
    <mesh file="meshes/AL4.STL" />
    <mesh file="meshes/AL5.STL" />
    <mesh file="meshes/AL6.STL" />
    <mesh file="meshes/AL7.STL" />

    <mesh file="meshes/AR1.STL" />
    <mesh file="meshes/AR2.STL" />
    <mesh file="meshes/AR3.STL" />
    <mesh file="meshes/AR4.STL" />
    <mesh file="meshes/AR5.STL" />
    <mesh file="meshes/AR6.STL" />
    <mesh file="meshes/AR7.STL" />

    <mesh file="meshes/Waist.STL" />
    <mesh file="meshes/Hip_Pitch_Left.STL" />
    <mesh file="meshes/Hip_Roll_Left.STL" />
    <mesh file="meshes/Hip_Yaw_Left.STL" />
    <mesh file="meshes/Shank_Left.STL" />
    <mesh file="meshes/Ankle_Cross_Left.STL" />
    <mesh file="meshes/left_foot_link.STL" />
    <mesh file="meshes/Hip_Pitch_Right.STL" />
    <mesh file="meshes/Hip_Roll_Right.STL" />
    <mesh file="meshes/Hip_Yaw_Right.STL" />
    <mesh file="meshes/Shank_Right.STL" />
    <mesh file="meshes/Ankle_Cross_Right.STL" />
    <mesh file="meshes/right_foot_link.STL" />
  </asset>

  <default>
    <default class="t1">
      <geom condim="1" contype="0" conaffinity="0" material="medium_gray" />
      <site rgba="1 0 0 1" size="0.01" group="5" />
      <default class="visual">
        <geom type="mesh" contype="0" conaffinity="0" group="2" />
      </default>
      <default class="collision">
        <geom group="3" />
        <default class="foot">
          <geom size="0.1115 0.05 0.015" pos="0.01 0 -0.015" type="box" contype="4" conaffinity="4" />
          <default class="foot_sphere">
            <geom contype="2" conaffinity="1" size=".01" type="sphere" />
          </default>
        </default>
      </default>

      <joint frictionloss="0.1" armature="0.005" />
      <position inheritrange="1" />

      <default class="head">
        <joint actuatorfrcrange="-7 7" damping="2" />
        <position kp="20" />
        <default class="head_yaw">
          <joint axis="0 0 1" range="-1.57 1.57" />
        </default>
        <default class="head_pitch">
          <joint axis="0 1 0" range="-0.35 1.22" />
        </default>
      </default>
      <default class="shoulder">
        <joint actuatorfrcrange="-18 18" damping="2" />
        <position kp="20" />
        <default class="shoulder_pitch">
          <joint axis="0 1 0" range="-3.31 1.22" />
        </default>
        <default class="shoulder_roll">
          <joint axis="1 0 0" />
        </default>
      </default>
      <default class="elbow">
        <joint actuatorfrcrange="-18 18" damping="2" />
        <position kp="20" />
        <default class="elbow_pitch">
          <joint axis="0 1 0" range="-2.27 2.27" />
        </default>
        <default class="elbow_yaw">
          <joint axis="0 0 1" range="-2.27 2.27" />
        </default>
      </default>
      <default class="wrist">
        <joint actuatorfrcrange="-18 18" damping="2" />
        <position kp="20" />
        <default class="wrist_pitch">
          <joint axis="0 1 0" range="-2.27 2.27" />
        </default>
        <default class="wrist_yaw">
          <joint axis="0 0 1" range="-2.27 2.27" />
        </default>
        <default class="hand_roll">
          <joint axis="1 0 0" range="-2.27 2.27" />
        </default>
      </default>
      <default class="waist">
        <joint axis="0 0 1" range="-1.57 1.57" actuatorfrcrange="-30 30" damping="3" />
        <position kp="50" />
      </default>
      <default class="hip">
        <default class="hip_pitch">
          <joint axis="0 1 0" range="-1.8 1.57" actuatorfrcrange="-45 45" damping="3" />
          <position kp="30" />
        </default>
        <default class="hip_roll">
          <joint axis="1 0 0" actuatorfrcrange="-30 30" damping="3" />
          <position kp="30" />
        </default>
        <default class="hip_yaw">
          <joint axis="0 0 1" range="-1 1" actuatorfrcrange="-30 30" damping="3" />
          <position kp="30" />
        </default>
      </default>
      <default class="knee">
        <joint axis="0 1 0" range="0 2.34" actuatorfrcrange="-60 60" damping="3" />
        <position kp="30" />
      </default>
      <default class="ankle">
        <position kp="10" />
        <joint damping="3" />
        <default class="ankle_pitch">
          <joint axis="0 1 0" range="-0.87 0.35" actuatorfrcrange="-20 20" />
        </default>
        <default class="ankle_roll">
          <joint axis="1 0 0" range="-0.44 0.44" actuatorfrcrange="-15 15" />
        </default>
      </default>
    </default>
  </default>

  <worldbody>
    <light name="spotlight" mode="targetbodycom" target="Trunk" pos="0 -2 4" exponent="20" />
    <body name="Trunk" pos="0 0 .7" childclass="t1">
      <freejoint />
      <inertial pos="0.0551365 -1.42058e-06 0.105062" quat="0.99996 1.40561e-05 -0.00899532 -1.39249e-05" mass="11.7"
        diaginertia="0.0915404 0.0767787 0.0556055" />
      <site name="imu" />
      <camera name="track" pos="1.248 -0.947 0.5" xyaxes="0.628 0.779 -0.000 -0.274 0.221 0.936" mode="trackcom" />
      <geom class="visual" material="light_gray" mesh="Trunk" />
      <geom class="collision" size="0.075 0.1 0.15" pos="0.06 0 0.12" type="box" />

      <body name="H1" pos="0.0625 0 0.243">
        <inertial pos="-0.000508 -0.001403 0.057432" quat="0.763881 -0.0132172 0.00173419 0.645219" mass="0.44391"
          diaginertia="0.000241549 0.00022351 0.000149941" />
        <joint name="AAHead_yaw" class="head_yaw" />
        <geom class="visual" mesh="H1" />
        <body name="H2" pos="0 0 0.06185">
          <inertial pos="0.007802 0.001262 0.098631" quat="0.988453 0.106172 -0.0745686 -0.0782786" mass="0.631019"
            diaginertia="0.00203553 0.00192467 0.00172381" />
          <joint name="Head_pitch" class="head_pitch" />
          <geom class="visual" mesh="H2" />
          <geom class="collision" size="0.08" pos="0.01 0 0.11" />
        </body>
      </body>

      <body name="AL1" pos="0.0575 0.1063 0.219" quat="1 0 0.000440565 0">
        <inertial pos="-0.000677 0.044974 0" quat="0.50423 0.495734 -0.50423 0.495734" mass="0.53"
          diaginertia="0.001367 0.00129329 0.000292711" />
        <joint name="Left_Shoulder_Pitch" class="shoulder_pitch" />
        <geom class="visual" material="light_gray" mesh="AL1" />
        <body name="AL2" pos="0 0.047 0">
          <inertial pos="0.003862 0.037976 0" quat="0.487991 0.511727 -0.487991 0.511727" mass="0.16"
            diaginertia="0.000401 0.00034538 0.00017662" />
          <joint name="Left_Shoulder_Roll" range="-1.74 1.57" class="shoulder_roll" />
          <geom class="visual" mesh="AL2" />
          <body name="AL3" pos="0.00025 0.0605 0">
            <inertial pos="0 0.085353 -9.9e-05" quat="0.70641 0.707803 0 0" mass="1.02"
              diaginertia="0.012869 0.012798 0.000620953" />
            <joint name="Left_Elbow_Pitch" class="elbow_pitch" />
            <geom class="visual" mesh="AL3" />
            <geom class="collision" size="0.03 0.075" pos="0 0.05 0" quat="0.707105 0.707108 0 0" type="cylinder" />

            <body name="AL4" pos="0 0.1471 0">
              <inertial pos="-0.00046851 0.062372 0.0015178" quat="0.708114 0.706086 -0.00272503 -0.00309075"
                mass="0.5570" diaginertia="0.0016731 0.00160801 0.00021389" />
              <joint name="Left_Elbow_Yaw" class="elbow_yaw" />
              <geom class="collision" size="0.04 0.07" pos="0 0.08 0" quat="0.707105 0.707108 0 0" type="cylinder" />
              <geom class="visual" type="mesh" mesh="AL4" />

              <body name="AL5" pos="0 0.105 0.00025">
                <inertial pos="-3.8402e-05 0.036076 0.0056711" quat="0.763252 0.646101 0 0" mass="0.43402"
                  diaginertia="0.000823 0.000801406 0.000199594" />
                <joint name="Left_Wrist_Pitch" class="wrist_pitch" />
                <geom class="visual" type="mesh" mesh="AL5" />

                <body name="AL6" pos="0 0.042 0">
                  <inertial pos="-0.00072939 0.056578 -0.0056257" quat="0.701498 0.712537 0.00305334 -0.0134832"
                    mass="0.47922" diaginertia="0.00117124 0.00113821 0.000165544" />
                  <joint name="Left_Wrist_Yaw" class="wrist_yaw" />
                  <geom class="visual" type="mesh" mesh="AL6" />

                  <body name="left_hand_link" pos="0.00475 0.07 0.0015">
                    <inertial pos="-0.0067917 0.06373 0.011867" quat="0.486792 0.512522 -0.512399 0.487649"
                      mass="0.30603" diaginertia="0.00244446 0.002302 0.000301541" />
                    <joint name="Left_Hand_Roll" class="hand_roll" />
                    <geom class="collision" size="0.06 0.075" pos="0 0.1 0" quat="0.707105 0.707108 0 0" type="cylinder" />
                    <geom class="visual" type="mesh" mesh="AL7" />
                  </body>
                </body>
              </body>
            </body>
          </body>
        </body>
      </body>


      <body name="AR1" pos="0.0575 -0.1063 0.219" quat="1 0 0.000440565 0">
        <inertial pos="-0.000677 -0.044974 0" quat="0.50423 0.495734 -0.50423 0.495734" mass="0.53"
          diaginertia="0.001367 0.00129329 0.000292711" />
        <joint name="Right_Shoulder_Pitch" class="shoulder_pitch" />
        <geom class="visual" material="light_gray" mesh="AR1" />
        <body name="AR2" pos="0 -0.047 0">
          <inertial pos="0.003862 -0.037976 0" quat="0.511727 0.487991 -0.511727 0.487991" mass="0.16"
            diaginertia="0.000401 0.00034538 0.00017662" />
          <joint name="Right_Shoulder_Roll" range="-1.57 1.74" class="shoulder_roll" />
          <geom class="visual" mesh="AR2" />
          <body name="AR3" pos="0.00025 -0.0605 0">
            <inertial pos="0 -0.085353 -9.9e-05" quat="0.707803 0.70641 0 0" mass="1.02"
              diaginertia="0.012869 0.012798 0.000620953" />
            <joint name="Right_Elbow_Pitch" class="elbow_pitch" />
            <geom class="visual" mesh="AR3" />
            <geom class="collision" size="0.03 0.075" pos="0 -0.05 0" quat="0.707105 0.707108 0 0" type="cylinder" />

            <body name="AR4" pos="0 -0.1471 0">
              <inertial pos="-0.0004573 -0.067734 0.0017465" quat="0.706214 0.70799 0.00258227 0.0022281" mass="0.5570"
                diaginertia="0.0022921 0.00222301 0.000233892" />
              <joint name="Right_Elbow_Yaw" class="elbow_yaw" />
              <geom class="collision" size="0.04 0.07" pos="0 -0.08 0" quat="0.707105 0.707108 0 0" type="cylinder" />
              <geom class="visual" type="mesh" mesh="AR4" />

              <body name="AR5" pos="0 -0.105 0.00025">
                <inertial pos="3.7355e-05 -0.035638 0.0053147" quat="0.648697 0.761046 0 0" mass="0.43402"
                  diaginertia="0.000836 0.000812239 0.000204761" />
                <joint name="Right_Wrist_Pitch" class="wrist_pitch" />
                <geom class="visual" type="mesh" mesh="AR5" />

                <body name="AR6" pos="0 -0.042 0">
                  <inertial pos="-0.0011437 -0.056205 -0.0056621" quat="0.711908 0.702081 0.0164127 -0.000464544"
                    mass="0.47922" diaginertia="0.00123856 0.00121017 0.000181264" />
                  <joint name="Right_Wrist_Yaw" class="wrist_yaw" />
                  <geom class="visual" type="mesh" mesh="AR6" />

                  <body name="right_hand_link" pos="0.00475 -0.07 0.0015">
                    <inertial pos="-0.0047758 -0.064411 0.011992" quat="0.488328 0.51175 -0.511877 0.487473"
                      mass="0.30603" diaginertia="0.00242288 0.002287 0.000287116" />
                    <!-- <inertial pos="-0.0047758 -0.064411 0.011992" quat="0.348921 0.444269 -0.615118 0.550009"
                    mass="0.24612" diaginertia="0.00164385 0.00156207 0.000212082" /> -->
                    <joint name="Right_Hand_Roll" class="hand_roll" />
                    <geom class="collision" size="0.06 0.075" pos="0 -0.1 0" quat="0.707105 0.707108 0 0"
                      type="cylinder" />
                    <geom class="visual" type="mesh" mesh="AR7" />
                  </body>
                </body>
              </body>
            </body>
          </body>
        </body>
      </body>

      <body name="Waist" pos="0.0625 0 -0.1155">
        <inertial pos="0.002284 3e-06 0.007301" quat="0.983649 0.000360386 -0.180076 0.00269791" mass="2.581"
          diaginertia="0.00536742 0.005299 0.00474258" />
        <joint name="Waist" class="waist" />
        <geom class="visual" mesh="Waist" />
        <body name="Hip_Pitch_Left" pos="0 0.106 0">
          <inertial pos="0.000534 -0.007296 -0.018083" quat="0.975141 0.2211 0.0145808 0.0017406" mass="1.021"
            diaginertia="0.00180547 0.00145926 0.00125327" />
          <joint name="Left_Hip_Pitch" class="hip_pitch" />
          <geom class="visual" material="light_gray" mesh="Hip_Pitch_Left" />
          <body name="Hip_Roll_Left" pos="0 0 -0.02">
            <inertial pos="0.001101 2.4e-05 -0.05375" quat="0.707081 -0.00599604 -0.00599604 0.707081" mass="0.385"
              diaginertia="0.001743 0.00151729 0.000514712" />
            <joint name="Left_Hip_Roll" range="-0.2 1.57" class="hip_roll" />
            <geom class="visual" mesh="Hip_Roll_Left" />
            <body name="Hip_Yaw_Left" pos="0 0 -0.081854">
              <inertial pos="-0.007233 0.000206 -0.089184" quat="0.696808 -0.033953 -0.0315708 0.715758" mass="2.166"
                diaginertia="0.0257334 0.0253024 0.00259215" />
              <joint name="Left_Hip_Yaw" class="hip_yaw" />
              <geom class="visual" mesh="Hip_Yaw_Left" />
              <geom class="collision" size="0.05 0.08" type="cylinder" />
              <body name="Shank_Left" pos="-0.014 0 -0.134">
                <inertial pos="-0.006012 0.000259 -0.124318" quat="0.997573 0.00144024 -0.023949 0.0653706" mass="1.73"
                  diaginertia="0.0346951 0.0345375 0.00185844" />
                <joint name="Left_Knee_Pitch" class="knee" />
                <geom class="visual" mesh="Shank_Left" />
                <geom class="collision" size="0.05 0.075" pos="0 0 -0.12" type="cylinder" />
                <body name="Ankle_Cross_Left" pos="0 0 -0.28">
                  <inertial pos="-0.003722 0 -0.007981" quat="0.443136 0.551027 0.551027 0.443136" mass="0.073"
                    diaginertia="2.9e-05 2.56589e-05 1.13411e-05" />
                  <joint name="Left_Ankle_Pitch" class="ankle_pitch" />
                  <geom class="visual" mesh="Ankle_Cross_Left" />
                  <body name="left_foot_link" pos="0 0.00025 -0.012">
                    <inertial pos="-0.000249 0 -0.00914" quat="0 0.620755 0 0.784005" mass="0.685"
                      diaginertia="0.00269786 0.002385 0.00218714" />
                    <joint name="Left_Ankle_Roll" class="ankle_roll" />
                    <geom class="visual" mesh="left_foot_link" />
                    <geom name="left_foot" class="foot" />
                    <site name="left_foot" />
                    <geom name="left_foot_1" class="foot_sphere" pos="0.1015 0.04 -0.02" />
                    <geom name="left_foot_2" class="foot_sphere" pos="0.1015 -0.04 -0.02" />
                    <geom name="left_foot_3" class="foot_sphere" pos="-0.1015 0.04 -0.02" />
                    <geom name="left_foot_4" class="foot_sphere" pos="-0.1015 -0.04 -0.02" />
                  </body>
                </body>
              </body>
            </body>
          </body>
        </body>
        <body name="Hip_Pitch_Right" pos="0 -0.106 0">
          <inertial pos="0.000534 0.007514 -0.018082" quat="0.973446 -0.228403 0.0147148 -0.00419349" mass="1.021"
            diaginertia="0.00180552 0.0014632 0.00124928" />
          <joint name="Right_Hip_Pitch" class="hip_pitch" />
          <geom class="visual" material="light_gray" mesh="Hip_Pitch_Right" />
          <body name="Hip_Roll_Right" pos="0 0 -0.02">
            <inertial pos="0.001099 2.4e-05 -0.053748" quat="0.707081 -0.00599604 -0.00599604 0.707081" mass="0.385"
              diaginertia="0.001743 0.00151729 0.000514712" />
            <joint name="Right_Hip_Roll" range="-1.57 0.2" class="hip_roll" />
            <geom class="visual" mesh="Hip_Roll_Right" />
            <body name="Hip_Yaw_Right" pos="0 0 -0.081854">
              <inertial pos="-0.007191 -0.000149 -0.08922" quat="0.714468 -0.0315638 -0.0336391 0.698146" mass="2.17"
                diaginertia="0.0257623 0.0253298 0.00259389" />
              <joint name="Right_Hip_Yaw" class="hip_yaw" />
              <geom class="visual" mesh="Hip_Yaw_Right" />
              <geom class="collision" size="0.05 0.08" type="cylinder" />
              <body name="Shank_Right" pos="-0.014 0 -0.134">
                <inertial pos="-0.005741 -0.000541 -0.122602" quat="0.99926 -0.000580963 -0.023461 -0.0304754"
                  mass="1.79" diaginertia="0.0351717 0.0349574 0.00196589" />
                <joint name="Right_Knee_Pitch" class="knee" />
                <geom class="visual" mesh="Shank_Right" />
                <geom class="collision" size="0.05 0.075" pos="0 0 -0.12" type="cylinder" />
                <body name="Ankle_Cross_Right" pos="0 0 -0.28">
                  <inertial pos="-0.003722 0 -0.007981" quat="0.443136 0.551027 0.551027 0.443136" mass="0.073"
                    diaginertia="2.9e-05 2.56589e-05 1.13411e-05" />
                  <joint name="Right_Ankle_Pitch" class="ankle_pitch" />
                  <geom class="visual" mesh="Ankle_Cross_Right" />
                  <body name="right_foot_link" pos="0 -0.00025 -0.012">
                    <inertial pos="-0.000248 0 -0.00914" quat="0 0.620755 0 0.784005" mass="0.685"
                      diaginertia="0.00269786 0.002385 0.00218714" />
                    <joint name="Right_Ankle_Roll" class="ankle_roll" />
                    <geom class="visual" mesh="right_foot_link" />
                    <geom name="right_foot" class="foot" />
                    <site name="right_foot" />
                    <geom name="right_foot_1" class="foot_sphere" pos="0.1015 0.04 -0.02" />
                    <geom name="right_foot_2" class="foot_sphere" pos="0.1015 -0.04 -0.02" />
                    <geom name="right_foot_3" class="foot_sphere" pos="-0.1015 0.04 -0.02" />
                    <geom name="right_foot_4" class="foot_sphere" pos="-0.1015 -0.04 -0.02" />
                  </body>
                </body>
              </body>
            </body>
          </body>
        </body>
      </body>
    </body>
  </worldbody>

  <sensor>
    <gyro site="imu" name="gyro" />
    <velocimeter site="imu" name="local_linvel" />
    <accelerometer site="imu" name="accelerometer" />
    <framezaxis objtype="site" objname="imu" name="upvector" />
    <framexaxis objtype="site" objname="imu" name="forwardvector" />
    <framelinvel objtype="site" objname="imu" name="global_linvel" />
    <frameangvel objtype="site" objname="imu" name="global_angvel" />
    <framepos objtype="site" objname="imu" name="position" />
    <framequat objtype="site" objname="imu" name="orientation" />
    <framelinvel objtype="site" objname="left_foot" name="left_foot_global_linvel" />
    <framelinvel objtype="site" objname="right_foot" name="right_foot_global_linvel" />
    <framepos objtype="site" objname="left_foot" name="left_foot_pos" />
    <framepos objtype="site" objname="right_foot" name="right_foot_pos" />
  </sensor>

  <actuator>
    <position class="head_yaw" name="AAHead_yaw" joint="AAHead_yaw" />
    <position class="head_pitch" name="Head_pitch" joint="Head_pitch" />

    <position class="shoulder_pitch" name="Left_Shoulder_Pitch" joint="Left_Shoulder_Pitch" />
    <position class="shoulder_roll" name="Left_Shoulder_Roll" joint="Left_Shoulder_Roll" />
    <position class="elbow_pitch" name="Left_Elbow_Pitch" joint="Left_Elbow_Pitch" />
    <position class="elbow_yaw" name="Left_Elbow_Yaw" joint="Left_Elbow_Yaw" />
    <position class="wrist_pitch" name="Left_Wrist_Pitch" joint="Left_Wrist_Pitch" />
    <position class="wrist_yaw" name="Left_Wrist_Yaw" joint="Left_Wrist_Yaw" />
    <position class="hand_roll" name="Left_Hand_Roll" joint="Left_Hand_Roll" />

    <position class="shoulder_pitch" name="Right_Shoulder_Pitch" joint="Right_Shoulder_Pitch" />
    <position class="shoulder_roll" name="Right_Shoulder_Roll" joint="Right_Shoulder_Roll" />
    <position class="elbow_pitch" name="Right_Elbow_Pitch" joint="Right_Elbow_Pitch" />
    <position class="elbow_yaw" name="Right_Elbow_Yaw" joint="Right_Elbow_Yaw" />
    <position class="wrist_pitch" name="Right_Wrist_Pitch" joint="Right_Wrist_Pitch" />
    <position class="wrist_yaw" name="Right_Wrist_Yaw" joint="Right_Wrist_Yaw" />
    <position class="hand_roll" name="Right_Hand_Roll" joint="Right_Hand_Roll" />

    <position class="waist" name="Waist" joint="Waist" />

    <position class="hip_pitch" name="Left_Hip_Pitch" joint="Left_Hip_Pitch" />
    <position class="hip_roll" name="Left_Hip_Roll" joint="Left_Hip_Roll" />
    <position class="hip_yaw" name="Left_Hip_Yaw" joint="Left_Hip_Yaw" />
    <position class="knee" name="Left_Knee_Pitch" joint="Left_Knee_Pitch" />
    <position class="ankle_pitch" name="Left_Ankle_Pitch" joint="Left_Ankle_Pitch" />
    <position class="ankle_roll" name="Left_Ankle_Roll" joint="Left_Ankle_Roll" />

    <position class="hip_pitch" name="Right_Hip_Pitch" joint="Right_Hip_Pitch" />
    <position class="hip_roll" name="Right_Hip_Roll" joint="Right_Hip_Roll" />
    <position class="hip_yaw" name="Right_Hip_Yaw" joint="Right_Hip_Yaw" />
    <position class="knee" name="Right_Knee_Pitch" joint="Right_Knee_Pitch" />
    <position class="ankle_pitch" name="Right_Ankle_Pitch" joint="Right_Ankle_Pitch" />
    <position class="ankle_roll" name="Right_Ankle_Roll" joint="Right_Ankle_Roll" />
  </actuator>
</mujoco>