<?xml version="1.0" encoding="utf-8"?>
<robot
  name="V23RobotAsm">
  <link
    name="Trunk">
    <inertial>
      <origin
        xyz="0.0551365401093076 -1.42058017623659E-06 0.105062332707657"
        rpy="0 0 0" />
      <mass
        value="11.7" />
      <inertia
        ixx="0.0915287235057927"
        ixy="-4.25369739206781E-07"
        ixz="0.000646360369011163"
        iyy="0.076778716903413"
        iyz="5.82340020271393E-07"
        izz="0.0556171053368987" />
    </inertial>
    <visual>
      <origin
        xyz="0 0 0"
        rpy="0 0 0" />
      <geometry>
        <mesh
          filename="7_dofs_arms_with_jaw/Trunk.STL" />
      </geometry>
      <material
        name="">
        <color
          rgba="0.76 0.76 0.76 0.2" />
      </material>
    </visual>
    <collision>
      <origin
        xyz="0 0 0"
        rpy="0 0 0" />
      <geometry>
        <mesh
          filename="7_dofs_arms_with_jaw/Trunk.STL" />
      </geometry>
    </collision>
  </link>
  <link
    name="H1">
    <inertial>
      <origin
        xyz="-0.000508 -0.001403 0.057432"
        rpy="0 0 0" />
      <mass
        value="0.443910" />
      <inertia
        ixx="0.000224"
        ixy="0.000003"
        ixz="0.000001"
        iyy="0.000241"
        iyz="-0.000002"
        izz="0.000150" />
    </inertial>
    <visual>
      <origin
        xyz="0 0 0"
        rpy="0 0 0" />
      <geometry>
        <mesh
          filename="7_dofs_arms_with_jaw/H1.STL" />
      </geometry>
      <material
        name="">
        <color
          rgba="0.4 0.4 0.4 0.3" />
      </material>
    </visual>
    <collision>
      <origin
        xyz="0 0 0"
        rpy="0 0 0" />
      <geometry>
        <mesh
          filename="7_dofs_arms_with_jaw/H1.STL" />
      </geometry>
    </collision>
  </link>
  <joint
    name="AAHead_yaw"
    type="revolute">
    <origin
      xyz="0.0625 0 0.243"
      rpy="0 0 0" />
    <parent
      link="Trunk" />
    <child
      link="H1" />
    <axis
      xyz="0 0 1" />
    <limit
      lower="0"
      upper="0"
      effort="0"
      velocity="0" />
  </joint>
  <link
    name="H2">
    <inertial>
      <origin
        xyz="0.007802 0.001262 0.098631"
        rpy="0 0 0" />
      <mass
        value="0.631019" />
      <inertia
        ixx="0.002025"
        ixy="-0.000025"
        ixz="0.000046"
        iyy="0.001920"
        iyz="0.000036"
        izz="0.001739" />
    </inertial>
    <visual>
      <origin
        xyz="0 0 0"
        rpy="0 0 0" />
      <geometry>
        <mesh
          filename="7_dofs_arms_with_jaw/H2.STL" />
      </geometry>
      <material
        name="">
        <color
          rgba="0.4 0.4 0.4 0.3" />
      </material>
    </visual>
    <collision>
      <origin
        xyz="0 0 0"
        rpy="0 0 0" />
      <geometry>
        <mesh
          filename="7_dofs_arms_with_jaw/H2.STL" />
      </geometry>
    </collision>
  </link>
  <joint
    name="Head_pitch"
    type="revolute">
    <origin
      xyz="0 0 0.06185"
      rpy="0 0 0" />
    <parent
      link="H1" />
    <child
      link="H2" />
    <axis
      xyz="0 1 0" />
    <limit
      lower="0"
      upper="0"
      effort="0"
      velocity="0" />
  </joint>
  <link
    name="AL1">
    <inertial>
      <origin
        xyz="-0.000677 0.044974 0.000000"
        rpy="0 0 0" />
      <mass
        value="0.53" />
      <inertia
        ixx="0.001293"
        ixy="-0.000017"
        ixz="0.000000"
        iyy="0.000293"
        iyz="0.000000"
        izz="0.001367" />
    </inertial>
    <visual>
      <origin
        xyz="0 0 0"
        rpy="0 0 0" />
      <geometry>
        <mesh
          filename="7_dofs_arms_with_jaw/AL1.STL" />
      </geometry>
      <material
        name="">
        <color
          rgba="0.76 0.76 0.76 0.2" />
      </material>
    </visual>
    <collision>
      <origin
        xyz="0 0 0"
        rpy="0 0 0" />
      <geometry>
        <mesh
          filename="7_dofs_arms_with_jaw/AL1.STL" />
      </geometry>
    </collision>
  </link>
  <joint
    name="Left_Shoulder_Pitch"
    type="revolute">
    <origin
      xyz="0.0575 0.1063 0.219"
      rpy="0 0.00088113 0" />
    <parent
      link="Trunk" />
    <child
      link="AL1" />
    <axis
      xyz="0 1 0" />
    <limit
      lower="0"
      upper="0"
      effort="0"
      velocity="0" />
  </joint>
  <link
    name="AL2">
    <inertial>
      <origin
        xyz="0.003862 0.037976 0.000000"
        rpy="0 0 0" />
      <mass
        value="0.160" />
      <inertia
        ixx="0.000345"
        ixy="0.000008"
        ixz="0.000000"
        iyy="0.000177"
        iyz="0.000000"
        izz="0.000401" />
    </inertial>
    <visual>
      <origin
        xyz="0 0 0"
        rpy="0 0 0" />
      <geometry>
        <mesh
          filename="7_dofs_arms_with_jaw/AL2.STL" />
      </geometry>
      <material
        name="">
        <color
          rgba="0.4 0.4 0.4 0.3" />
      </material>
    </visual>
    <collision>
      <origin
        xyz="0 0 0"
        rpy="0 0 0" />
      <geometry>
        <mesh
          filename="7_dofs_arms_with_jaw/AL2.STL" />
      </geometry>
    </collision>
  </link>
  <joint
    name="Left_Shoulder_Roll"
    type="revolute">
    <origin
      xyz="0 0.047 0"
      rpy="0 0 0" />
    <parent
      link="AL1" />
    <child
      link="AL2" />
    <axis
      xyz="1 0 0" />
    <limit
      lower="0"
      upper="0"
      effort="0"
      velocity="0" />
  </joint>
  <link
    name="AL3">
    <inertial>
      <origin
        xyz="0.000000 0.085353 -0.000099"
        rpy="0 0 0" />
      <mass
        value="1.02" />
      <inertia
        ixx="0.012869"
        ixy="0.000000"
        ixz="0.000000"
        iyy="0.000621"
        iyz="-0.000024"
        izz="0.012798" />
    </inertial>
    <visual>
      <origin
        xyz="0 0 0"
        rpy="0 0 0" />
      <geometry>
        <mesh
          filename="7_dofs_arms_with_jaw/AL3.STL" />
      </geometry>
      <material
        name="">
        <color
          rgba="0.4 0.4 0.4 0.3" />
      </material>
    </visual>
    <collision>
      <origin
        xyz="0 0 0"
        rpy="0 0 0" />
      <geometry>
        <mesh
          filename="7_dofs_arms_with_jaw/AL3.STL" />
      </geometry>
    </collision>
  </link>
  <joint
    name="Left_Elbow_Pitch"
    type="revolute">
    <origin
      xyz="0.00025 0.0605 0"
      rpy="0 0 0" />
    <parent
      link="AL2" />
    <child
      link="AL3" />
    <axis
      xyz="0 1 0" />
    <limit
      lower="0"
      upper="0"
      effort="0"
      velocity="0" />
  </joint>

<link
    name="AL4">
    <inertial>
      <origin
        xyz="-0.00046851 0.062372 0.0015178"
        rpy="0 0 0" />
      <mass
        value="0.2984" />
      <inertia
        ixx="0.001673"
        ixy="-1.2E-05"
        ixz="0"
        iyy="0.000214"
        iyz="4E-06"
        izz="0.001608" />
    </inertial>
    <visual>
      <origin
        xyz="0 0 0"
        rpy="0 0 0" />
      <geometry>
        <mesh
          filename="7_dofs_arms_with_jaw/AL4.STL" />
      </geometry>
      <material
        name="">
        <color
          rgba="0.75294 0.75294 0.75294 1" />
      </material>
    </visual>
    <collision>
      <origin
        xyz="0 0 0"
        rpy="0 0 0" />
      <geometry>
        <mesh
          filename="7_dofs_arms_with_jaw/AL4.STL" />
      </geometry>
    </collision>
  </link>
  <joint
    name="Left_Elbow_Yaw"
    type="revolute">
    <origin
      xyz="0 0.1471 0"
      rpy="0 0 0" />
    <parent
      link="AL3" />
    <child
      link="AL4" />
    <axis
      xyz="0 0 1" />
    <limit
      lower="0"
      upper="0"
      effort="0"
      velocity="0" />
  </joint>
  <link
    name="AL5">
    <inertial>
      <origin
        xyz="-3.8402E-05 0.036076 0.0056711"
        rpy="0 0 0" />
      <mass
        value="0.42219" />
      <inertia
        ixx="0.000823"
        ixy="0"
        ixz="0"
        iyy="0.000216"
        iyz="9.8E-05"
        izz="0.000785" />
    </inertial>
    <visual>
      <origin
        xyz="0 0 0"
        rpy="0 0 0" />
      <geometry>
        <mesh
          filename="7_dofs_arms_with_jaw/AL5.STL" />
      </geometry>
      <material
        name="">
        <color
          rgba="0.75294 0.75294 0.75294 1" />
      </material>
    </visual>
    <collision>
      <origin
        xyz="0 0 0"
        rpy="0 0 0" />
      <geometry>
        <mesh
          filename="7_dofs_arms_with_jaw/AL5.STL" />
      </geometry>
    </collision>
  </link>
  <joint
    name="Left_Wrist_Pitch"
    type="revolute">
    <origin
      xyz="0 0.105 0.00025"
      rpy="0 0 0" />
    <parent
      link="AL4" />
    <child
      link="AL5" />
    <axis
      xyz="0 1 0" />
    <limit
      lower="0"
      upper="0"
      effort="0"
      velocity="0" />
  </joint>
  <link
    name="AL6">
    <inertial>
      <origin
        xyz="-0.00072939 0.056578 -0.0056257"
        rpy="0 0 0" />
      <mass
        value="0.26532" />
      <inertia
        ixx="0.001171"
        ixy="-1.5E-05"
        ixz="-1E-06"
        iyy="0.000166"
        iyz="-1.5E-05"
        izz="0.001138" />
    </inertial>
    <visual>
      <origin
        xyz="0 0 0"
        rpy="0 0 0" />
      <geometry>
        <mesh
          filename="7_dofs_arms_with_jaw/AL6.STL" />
      </geometry>
      <material
        name="">
        <color
          rgba="0.75294 0.75294 0.75294 1" />
      </material>
    </visual>
    <collision>
      <origin
        xyz="0 0 0"
        rpy="0 0 0" />
      <geometry>
        <mesh
          filename="7_dofs_arms_with_jaw/AL6.STL" />
      </geometry>
    </collision>
  </link>
  <joint
    name="Left_Wrist_Yaw"
    type="revolute">
    <origin
      xyz="0 0.042 0"
      rpy="0 0 0" />
    <parent
      link="AL5" />
    <child
      link="AL6" />
    <axis
      xyz="0 0 1" />
    <limit
      lower="0"
      upper="0"
      effort="0"
      velocity="0" />
  </joint>
  <link
    name="left_hand_link">
    <inertial>
      <origin
        xyz="-0.0067917 0.06373 0.011867"
        rpy="0 0 0" />
      <mass
        value="0.24875" />
      <inertia
        ixx="0.001568"
        ixy="-9.4E-05"
        ixz="-1.9E-05"
        iyy="0.000259"
        iyz="0.000214"
        izz="0.001609" />
    </inertial>
    <visual>
      <origin
        xyz="0 0 0"
        rpy="0 0 0" />
      <geometry>
        <mesh
          filename="7_dofs_arms_with_jaw/AL77.STL" />
      </geometry>
      <material
        name="">
        <color
          rgba="0.75294 0.75294 0.75294 1" />
      </material>
    </visual>
    <collision>
      <origin
        xyz="0 0 0"
        rpy="0 0 0" />
      <geometry>
        <mesh
          filename="7_dofs_arms_with_jaw/AL77.STL" />
      </geometry>
    </collision>
  </link>
  <joint
    name="Left_Hand_Roll"
    type="revolute">
    <origin
      xyz="0.00475 0.07 0.0015"
      rpy="0 0 0" />
    <parent
      link="AL6" />
    <child
      link="left_hand_link" />
    <axis
      xyz="1 0 0" />
    <limit
      lower="0"
      upper="0"
      effort="0"
      velocity="0" />
  </joint>




<link
    name="left_base_link">
    <inertial>
      <origin
        xyz="0.00339303654278191 -2.1205433560656E-05 -0.0099185365078758"
        rpy="0 0 0" />
      <mass
        value="0.105853592307918" />
      <inertia
        ixx="3.93795927851199E-05"
        ixy="-8.7395226509728E-08"
        ixz="5.91928672040786E-07"
        iyy="0.000106376720416166"
        iyz="-1.82858764303774E-10"
        izz="0.000125852616063213" />
    </inertial>
    <visual>
      <origin
        xyz="0 0 0"
        rpy="0 0 0" />
      <geometry>
        <mesh
          filename="7_dofs_arms_with_jaw/left_base_link.STL" />
      </geometry>
      <material
        name="">
        <color
          rgba="0.894117647058823 0.913725490196078 0.929411764705882 1" />
      </material>
    </visual>
    <collision>
      <origin
        xyz="0 0 0"
        rpy="0 0 0" />
      <geometry>
        <mesh
          filename="7_dofs_arms_with_jaw/left_base_link.STL" />
      </geometry>
    </collision>
  </link>
  

<joint
    name="left_base_link"
    type="fixed">
    <origin
      xyz="-0.006 0.08 0.01"
      rpy="0 0 1.5708" />
    <parent
      link="left_hand_link" />
    <child
      link="left_base_link" />
    <axis
      xyz="1 0 0" />
    <limit
      lower="0"
      upper="1"
      effort="1"
      velocity="1" />
  </joint>





<link
    name="left_Link1">
    <inertial>
      <origin
        xyz="0.0164149658242926 9.75754915755189E-09 0.00898193900447147"
        rpy="0 0 0" />
      <mass
        value="0.00647716099397792" />
      <inertia
        ixx="2.95068972140683E-07"
        ixy="8.63208170411155E-13"
        ixz="-1.92008628754607E-09"
        iyy="1.69979619476872E-06"
        iyz="-1.99232397395103E-13"
        izz="1.45016449434989E-06" />
    </inertial>
    <visual>
      <origin
        xyz="0 0 0"
        rpy="0 0 0" />
      <geometry>
        <mesh
          filename="7_dofs_arms_with_jaw/left_Link1.STL" />
      </geometry>
      <material
        name="">
        <color
          rgba="0.894117647058823 0.913725490196078 0.929411764705882 1" />
      </material>
    </visual>
    <collision>
      <origin
        xyz="0 0 0"
        rpy="0 0 0" />
      <geometry>
        <mesh
          filename="7_dofs_arms_with_jaw/left_Link1.STL" />
      </geometry>
    </collision>
  </link>
  <joint
    name="left_Link1"
    type="revolute">
    <origin
      xyz="0.036 -0.04 -0.019"
      rpy="-3.0158E-16 -7.1586E-16 -0.30719" />
    <parent
      link="left_base_link" />
    <child
      link="left_Link1" />
    <axis
      xyz="0 1 0" />
    <limit
      lower="0"
      upper="1"
      effort="1"
      velocity="1" />
  </joint>
  <link
    name="left_Link11">
    <inertial>
      <origin
        xyz="0.011366555972498 0.0118642725662323 0.0060000073930068"
        rpy="0 0 0" />
      <mass
        value="0.0127543420299361" />
      <inertia
        ixx="5.68538478020233E-07"
        ixy="-2.68012262729007E-07"
        ixz="9.34125984931838E-13"
        iyy="1.45145776457487E-06"
        iyz="9.34355360561326E-13"
        izz="1.50564598220449E-06" />
    </inertial>
    <visual>
      <origin
        xyz="0 0 0"
        rpy="0 0 0" />
      <geometry>
        <mesh
          filename="7_dofs_arms_with_jaw/left_Link11.STL" />
      </geometry>
      <material
        name="">
        <color
          rgba="0.894117647058823 0.913725490196078 0.929411764705882 1" />
      </material>
    </visual>
    <collision>
      <origin
        xyz="0 0 0"
        rpy="0 0 0" />
      <geometry>
        <mesh
          filename="7_dofs_arms_with_jaw/left_Link11.STL" />
      </geometry>
    </collision>
  </link>
  <joint
    name="left_Link11"
    type="revolute">
    <origin
      xyz="0.042 0 0.003"
      rpy="5.0393E-16 5.6225E-16 0.30719" />
    <parent
      link="left_Link1" />
    <child
      link="left_Link11" />
    <axis
      xyz="0 1 0" />
    <limit
      lower="-1"
      upper="0"
      effort="1"
      velocity="1" />
  </joint>
  <link
    name="left_Link2">
    <inertial>
      <origin
        xyz="0.0164149658242926 9.75754915755189E-09 0.00898193900447147"
        rpy="0 0 0" />
      <mass
        value="0.00647716099397793" />
      <inertia
        ixx="2.95068972140683E-07"
        ixy="8.63208169650113E-13"
        ixz="-1.92008628755341E-09"
        iyy="1.69979619476872E-06"
        iyz="-1.99232397320157E-13"
        izz="1.45016449434989E-06" />
    </inertial>
    <visual>
      <origin
        xyz="0 0 0"
        rpy="0 0 0" />
      <geometry>
        <mesh
          filename="7_dofs_arms_with_jaw/left_Link2.STL" />
      </geometry>
      <material
        name="">
        <color
          rgba="0.894117647058823 0.913725490196078 0.929411764705882 1" />
      </material>
    </visual>
    <collision>
      <origin
        xyz="0 0 0"
        rpy="0 0 0" />
      <geometry>
        <mesh
          filename="7_dofs_arms_with_jaw/left_Link2.STL" />
      </geometry>
    </collision>
  </link>
  <joint
    name="left_Link2"
    type="revolute">
    <origin
      xyz="0.036 0.04 -0.019"
      rpy="-2.6397E-16 3.7199E-16 0.30719" />
    <parent
      link="left_base_link" />
    <child
      link="left_Link2" />
    <axis
      xyz="0 1 0" />
    <limit
      lower="-1"
      upper="0"
      effort="1"
      velocity="1" />
  </joint>
  <link
    name="left_Link22">
    <inertial>
      <origin
        xyz="-0.011366555972498 0.0118642725662323 -0.0060000073930068"
        rpy="0 0 0" />
      <mass
        value="0.0127543420299362" />
      <inertia
        ixx="5.68538478020238E-07"
        ixy="2.6801226272901E-07"
        ixz="9.34125986250171E-13"
        iyy="1.45145776457489E-06"
        iyz="-9.34355361631596E-13"
        izz="1.5056459822045E-06" />
    </inertial>
    <visual>
      <origin
        xyz="0 0 0"
        rpy="0 0 0" />
      <geometry>
        <mesh
          filename="7_dofs_arms_with_jaw/left_Link22.STL" />
      </geometry>
      <material
        name="">
        <color
          rgba="0.894117647058823 0.913725490196078 0.929411764705882 1" />
      </material>
    </visual>
    <collision>
      <origin
        xyz="0 0 0"
        rpy="0 0 0" />
      <geometry>
        <mesh
          filename="7_dofs_arms_with_jaw/left_Link22.STL" />
      </geometry>
    </collision>
  </link>
  <joint
    name="left_Link22"
    type="revolute">
    <origin
      xyz="0.042 0 0.015"
      rpy="-3.641E-16 2.4584E-16 2.8344" />
    <parent
      link="left_Link2" />
    <child
      link="left_Link22" />
    <axis
      xyz="0 1 0" />
    <limit
      lower="0"
      upper="1"
      effort="1"
      velocity="1" />
  </joint>








  <link
    name="AR1">
    <inertial>
      <origin
        xyz="-0.000677 -0.044974 0.000000"
        rpy="0 0 0" />
      <mass
        value="0.53" />
      <inertia
        ixx="0.001293"
        ixy="-0.000017"
        ixz="0.000000"
        iyy="0.000293"
        iyz="0.000000"
        izz="0.001367" />
    </inertial>
    <visual>
      <origin
        xyz="0 0 0"
        rpy="0 0 0" />
      <geometry>
        <mesh
          filename="7_dofs_arms_with_jaw/AR1.STL" />
      </geometry>
      <material
        name="">
        <color
          rgba="0.76 0.76 0.76 0.2" />
      </material>
    </visual>
    <collision>
      <origin
        xyz="0 0 0"
        rpy="0 0 0" />
      <geometry>
        <mesh
          filename="7_dofs_arms_with_jaw/AR1.STL" />
      </geometry>
    </collision>
  </link>
  <joint
    name="Right_Shoulder_Pitch"
    type="revolute">
    <origin
      xyz="0.0575 -0.1063 0.219"
      rpy="0 0.00088113 0" />
    <parent
      link="Trunk" />
    <child
      link="AR1" />
    <axis
      xyz="0 1 0" />
    <limit
      lower="0"
      upper="0"
      effort="0"
      velocity="0" />
  </joint>
  <link
    name="AR2">
    <inertial>
      <origin
        
xyz="0.003862 -0.037976 0.000000"
        rpy="0 0 0" />
      <mass
        value="0.160" />
      <inertia
        ixx="0.000345"
        ixy="-0.000008"
        ixz="0.000000"
        iyy="0.000177"
        iyz="0.000000"
        izz="0.000401" />
    </inertial>
    <visual>
      <origin
        xyz="0 0 0"
        rpy="0 0 0" />
      <geometry>
        <mesh
          filename="7_dofs_arms_with_jaw/AR2.STL" />
      </geometry>
      <material
        name="">
        <color
          rgba="0.4 0.4 0.4 0.3" />
      </material>
    </visual>
    <collision>
      <origin
        xyz="0 0 0"
        rpy="0 0 0" />
      <geometry>
        <mesh
          filename="7_dofs_arms_with_jaw/AR2.STL" />
      </geometry>
    </collision>
  </link>
  <joint
    name="Right_Shoulder_Roll"
    type="revolute">
    <origin
      xyz="0 -0.047 0"
      rpy="0 0 0" />
    <parent
      link="AR1" />
    <child
      link="AR2" />
    <axis
      xyz="1 0 0" />
    <limit
      lower="0"
      upper="0"
      effort="0"
      velocity="0" />
  </joint>
  <link
    name="AR3">
    <inertial>
      <origin  
 xyz="0.000000 -0.085353 -0.000099"
        rpy="0 0 0" />
      <mass
        value="1.02" />
      <inertia
        ixx="0.012869"
        ixy="0.000000"
        ixz="0.000000"
        iyy="0.000621"
        iyz="0.000024"
        izz="0.012798" />
    </inertial>
    <visual>
      <origin
        xyz="0 0 0"
        rpy="0 0 0" />
      <geometry>
        <mesh
          filename="7_dofs_arms_with_jaw/AR3.STL" />
      </geometry>
      <material
        name="">
        <color
          rgba="0.4 0.4 0.4 0.3" />
      </material>
    </visual>
    <collision>
      <origin
        xyz="0 0 0"
        rpy="0 0 0" />
      <geometry>
        <mesh
          filename="7_dofs_arms_with_jaw/AR3.STL" />
      </geometry>
    </collision>
  </link>
  <joint
    name="Right_Elbow_Pitch"
    type="revolute">
    <origin
      xyz="0.00025 -0.0605 0"
      rpy="0 0 0" />
    <parent
      link="AR2" />
    <child
      link="AR3" />
    <axis
      xyz="0 1 0" />
    <limit
      lower="0"
      upper="0"
      effort="0"
      velocity="0" />
  </joint>



  <link
    name="AR4">
    <inertial>
      <origin
        xyz="-0.0004573 -0.067734 0.0017465"
        rpy="0 0 0" />
      <mass
        value="0.3599" />
      <inertia
        ixx="0.002292"
        ixy="1.4E-05"
        ixz="0"
        iyy="0.000234"
        iyz="-5E-06"
        izz="0.002223" />
    </inertial>
    <visual>
      <origin
        xyz="0 0 0"
        rpy="0 0 0" />
      <geometry>
        <mesh
          filename="7_dofs_arms_with_jaw/AR4.STL" />
      </geometry>
      <material
        name="">
        <color
          rgba="0.75294 0.75294 0.75294 1" />
      </material>
    </visual>
    <collision>
      <origin
        xyz="0 0 0"
        rpy="0 0 0" />
      <geometry>
        <mesh
          filename="7_dofs_arms_with_jaw/AR4.STL" />
      </geometry>
    </collision>
  </link>
  <joint
    name="Right_Elbow_Yaw"
    type="revolute">
    <origin
      xyz="0 -0.1471 0"
      rpy="0 0 0" />
    <parent
      link="AR3" />
    <child
      link="AR4" />
    <axis
      xyz="0 0 1" />
    <limit
      lower="0"
      upper="0"
      effort="0"
      velocity="0" />
  </joint>
  <link
    name="AR5">
    <inertial>
      <origin
        xyz="3.7355E-05 -0.035638 0.0053147"
        rpy="0 0 0" />
      <mass
        value="0.43402" />
      <inertia
        ixx="0.000836"
        ixy="0"
        ixz="0"
        iyy="0.00022"
        iyz="-9.5E-05"
        izz="0.000797" />
    </inertial>
    <visual>
      <origin
        xyz="0 0 0"
        rpy="0 0 0" />
      <geometry>
        <mesh
          filename="7_dofs_arms_with_jaw/AR5.STL" />
      </geometry>
      <material
        name="">
        <color
          rgba="0.75294 0.75294 0.75294 1" />
      </material>
    </visual>
    <collision>
      <origin
        xyz="0 0 0"
        rpy="0 0 0" />
      <geometry>
        <mesh
          filename="7_dofs_arms_with_jaw/AR5.STL" />
      </geometry>
    </collision>
  </link>
  <joint
    name="Right_Wrist_Pitch"
    type="revolute">
    <origin
      xyz="0 -0.105 0.00025"
      rpy="0 0 0" />
    <parent
      link="AR4" />
    <child
      link="AR5" />
    <axis
      xyz="0 1 0" />
    <limit
      lower="0"
      upper="0"
      effort="0"
      velocity="0" />
  </joint>
  <link
    name="AR6">
    <inertial>
      <origin
        xyz="-0.0011437 -0.056205 -0.0056621"
        rpy="0 0 0" />
      <mass
        value="0.28215" />
      <inertia
        ixx="0.001238"
        ixy="2.4E-05"
        ixz="-1E-06"
        iyy="0.000182"
        iyz="1.4E-05"
        izz="0.00121" />
    </inertial>
    <visual>
      <origin
        xyz="0 0 0"
        rpy="0 0 0" />
      <geometry>
        <mesh
          filename="7_dofs_arms_with_jaw/AR6.STL" />
      </geometry>
      <material
        name="">
        <color
          rgba="0.75294 0.75294 0.75294 1" />
      </material>
    </visual>
    <collision>
      <origin
        xyz="0 0 0"
        rpy="0 0 0" />
      <geometry>
        <mesh
          filename="7_dofs_arms_with_jaw/AR6.STL" />
      </geometry>
    </collision>
  </link>
  <joint
    name="Right_Wrist_Yaw"
    type="revolute">
    <origin
      xyz="0 -0.042 0"
      rpy="0 0 0" />
    <parent
      link="AR5" />
    <child
      link="AR6" />
    <axis
      xyz="0 0 1" />
    <limit
      lower="0"
      upper="0"
      effort="0"
      velocity="0" />
  </joint>
  <link
    name="right_hand_link">
    <inertial>
      <origin
        xyz="-0.0047758 -0.064411 0.011992"
        rpy="0 0 0" />
      <mass
        value="0.24612" />
      <inertia
        ixx="0.001568"
        ixy="8.4E-05"
        ixz="-1.5E-05"
        iyy="0.00025"
        iyz="-0.000214"
        izz="0.0016" />
    </inertial>
    <visual>
      <origin
        xyz="0 0 0"
        rpy="0 0 0" />
      <geometry>
        <mesh
          filename="7_dofs_arms_with_jaw/AR77.STL" />
      </geometry>
      <material
        name="">
        <color
          rgba="0.75294 0.75294 0.75294 1" />
      </material>
    </visual>
    <collision>
      <origin
        xyz="0 0 0"
        rpy="0 0 0" />
      <geometry>
        <mesh
          filename="7_dofs_arms_with_jaw/AR77.STL" />
      </geometry>
    </collision>
  </link>
  <joint
    name="Right_Hand_Roll"
    type="revolute">
    <origin
      xyz="0.00475 -0.07 0.0015"
      rpy="0 0 0" />
    <parent
      link="AR6" />
    <child
      link="right_hand_link" />
    <axis
      xyz="1 0 0" />
    <limit
      lower="0"
      upper="0"
      effort="0"
      velocity="0" />
  </joint>




<link
    name="right_base_link">
    <inertial>
      <origin
        xyz="0.00339303654278191 -2.1205433560656E-05 -0.0099185365078758"
        rpy="0 0 0" />
      <mass
        value="0.105853592307918" />
      <inertia
        ixx="3.93795927851199E-05"
        ixy="-8.7395226509728E-08"
        ixz="5.91928672040786E-07"
        iyy="0.000106376720416166"
        iyz="-1.82858764303774E-10"
        izz="0.000125852616063213" />
    </inertial>
    <visual>
      <origin
        xyz="0 0 0"
        rpy="0 0 0" />
      <geometry>
        <mesh
          filename="7_dofs_arms_with_jaw/right_base_link.STL" />
      </geometry>
      <material
        name="">
        <color
          rgba="0.894117647058823 0.913725490196078 0.929411764705882 1" />
      </material>
    </visual>
    <collision>
      <origin
        xyz="0 0 0"
        rpy="0 0 0" />
      <geometry>
        <mesh
          filename="7_dofs_arms_with_jaw/right_base_link.STL" />
      </geometry>
    </collision>
  </link>
  

<joint
    name="right_base_link"
    type="fixed">
    <origin
      xyz="-0.006 -0.084 0.01"
      rpy="0 0 -1.5708" />
    <parent
      link="right_hand_link" />
    <child
      link="right_base_link" />
    <axis
      xyz="1 0 0" />
    <limit
      lower="0"
      upper="1"
      effort="1"
      velocity="1" />
  </joint>





<link
    name="right_Link1">
    <inertial>
      <origin
        xyz="0.0164149658242926 9.75754915755189E-09 0.00898193900447147"
        rpy="0 0 0" />
      <mass
        value="0.00647716099397792" />
      <inertia
        ixx="2.95068972140683E-07"
        ixy="8.63208170411155E-13"
        ixz="-1.92008628754607E-09"
        iyy="1.69979619476872E-06"
        iyz="-1.99232397395103E-13"
        izz="1.45016449434989E-06" />
    </inertial>
    <visual>
      <origin
        xyz="0 0 0"
        rpy="0 0 0" />
      <geometry>
        <mesh
          filename="7_dofs_arms_with_jaw/right_Link1.STL" />
      </geometry>
      <material
        name="">
        <color
          rgba="0.894117647058823 0.913725490196078 0.929411764705882 1" />
      </material>
    </visual>
    <collision>
      <origin
        xyz="0 0 0"
        rpy="0 0 0" />
      <geometry>
        <mesh
          filename="7_dofs_arms_with_jaw/right_Link1.STL" />
      </geometry>
    </collision>
  </link>
  <joint
    name="right_Link1"
    type="revolute">
    <origin
      xyz="0.036 -0.04 -0.019"
      rpy="0 0 -0.30719" />
    <parent
      link="right_base_link" />
    <child
      link="right_Link1" />
    <axis
      xyz="0 1 0" />
    <limit
      lower="0"
      upper="1"
      effort="1"
      velocity="1" />
  </joint>
  <link
    name="right_Link11">
    <inertial>
      <origin
        xyz="0.011366555972498 0.0118642725662323 0.0060000073930068"
        rpy="0 0 0" />
      <mass
        value="0.0127543420299361" />
      <inertia
        ixx="5.68538478020233E-07"
        ixy="-2.68012262729007E-07"
        ixz="9.34125984931838E-13"
        iyy="1.45145776457487E-06"
        iyz="9.34355360561326E-13"
        izz="1.50564598220449E-06" />
    </inertial>
    <visual>
      <origin
        xyz="0 0 0"
        rpy="0 0 0" />
      <geometry>
        <mesh
          filename="7_dofs_arms_with_jaw/right_Link11.STL" />
      </geometry>
      <material
        name="">
        <color
          rgba="0.894117647058823 0.913725490196078 0.929411764705882 1" />
      </material>
    </visual>
    <collision>
      <origin
        xyz="0 0 0"
        rpy="0 0 0" />
      <geometry>
        <mesh
          filename="7_dofs_arms_with_jaw/right_Link11.STL" />
      </geometry>
    </collision>
  </link>
  <joint
    name="right_Link11"
    type="revolute">
    <origin
      xyz="0.042 0 0.003"
      rpy="5.0393E-16 5.6225E-16 0.30719" />
    <parent
      link="right_Link1" />
    <child
      link="right_Link11" />
    <axis
      xyz="0 1 0" />
    <limit
      lower="-1"
      upper="0"
      effort="1"
      velocity="1" />
  </joint>
  <link
    name="right_Link2">
    <inertial>
      <origin
        xyz="0.0164149658242926 9.75754915755189E-09 0.00898193900447147"
        rpy="0 0 0" />
      <mass
        value="0.00647716099397793" />
      <inertia
        ixx="2.95068972140683E-07"
        ixy="8.63208169650113E-13"
        ixz="-1.92008628755341E-09"
        iyy="1.69979619476872E-06"
        iyz="-1.99232397320157E-13"
        izz="1.45016449434989E-06" />
    </inertial>
    <visual>
      <origin
        xyz="0 0 0"
        rpy="0 0 0" />
      <geometry>
        <mesh
          filename="7_dofs_arms_with_jaw/right_Link2.STL" />
      </geometry>
      <material
        name="">
        <color
          rgba="0.894117647058823 0.913725490196078 0.929411764705882 1" />
      </material>
    </visual>
    <collision>
      <origin
        xyz="0 0 0"
        rpy="0 0 0" />
      <geometry>
        <mesh
          filename="7_dofs_arms_with_jaw/right_Link2.STL" />
      </geometry>
    </collision>
  </link>
  <joint
    name="right_Link2"
    type="revolute">
    <origin
      xyz="0.036 0.04 -0.019"
      rpy="-2.6397E-16 3.7199E-16 0.30719" />
    <parent
      link="right_base_link" />
    <child
      link="right_Link2" />
    <axis
      xyz="0 1 0" />
    <limit
      lower="-1"
      upper="0"
      effort="1"
      velocity="1" />
  </joint>
  <link
    name="right_Link22">
    <inertial>
      <origin
        xyz="-0.011366555972498 0.0118642725662323 -0.0060000073930068"
        rpy="0 0 0" />
      <mass
        value="0.0127543420299362" />
      <inertia
        ixx="5.68538478020238E-07"
        ixy="2.6801226272901E-07"
        ixz="9.34125986250171E-13"
        iyy="1.45145776457489E-06"
        iyz="-9.34355361631596E-13"
        izz="1.5056459822045E-06" />
    </inertial>
    <visual>
      <origin
        xyz="0 0 0"
        rpy="0 0 0" />
      <geometry>
        <mesh
          filename="7_dofs_arms_with_jaw/right_Link22.STL" />
      </geometry>
      <material
        name="">
        <color
          rgba="0.894117647058823 0.913725490196078 0.929411764705882 1" />
      </material>
    </visual>
    <collision>
      <origin
        xyz="0 0 0"
        rpy="0 0 0" />
      <geometry>
        <mesh
          filename="7_dofs_arms_with_jaw/right_Link22.STL" />
      </geometry>
    </collision>
  </link>
  <joint
    name="right_Link22"
    type="revolute">
    <origin
      xyz="0.042 0 0.015"
      rpy="-3.641E-16 2.4584E-16 2.8344" />
    <parent
      link="right_Link2" />
    <child
      link="right_Link22" />
    <axis
      xyz="0 1 0" />
    <limit
      lower="0"
      upper="1"
      effort="1"
      velocity="1" />
  </joint>











  <link
    name="Waist">
    <inertial>
      <origin
        xyz="0.002284 0.000003 0.007301"
        rpy="0 0 0" />
      <mass
        value="2.581" />
      <inertia
        ixx="0.005289"
        ixy="0.000000"
        ixz="0.000207"
        iyy="0.005299"
        iyz="0.000001"
        izz="0.004821" />
    </inertial>
    <visual>
      <origin
        xyz="0 0 0"
        rpy="0 0 0" />
      <geometry>
        <mesh
          filename="7_dofs_arms_with_jaw/Waist.STL" />
      </geometry>
      <material
        name="">
        <color
          rgba="0.4 0.4 0.4 0.3" />
      </material>
    </visual>
    <collision>
      <origin
        xyz="0 0 0"
        rpy="0 0 0" />
      <geometry>
        <mesh
          filename="7_dofs_arms_with_jaw/Waist.STL" />
      </geometry>
    </collision>
  </link>
  <joint
    name="Waist"
    type="revolute">
    <origin
      xyz="0.0625 0 -0.1155"
      rpy="0 0 0" />
    <parent
      link="Trunk" />
    <child
      link="Waist" />
    <axis
      xyz="0 0 1" />
    <limit
      lower="0"
      upper="0"
      effort="0"
      velocity="0" />
  </joint>
  <link
    name="Hip_Pitch_Left">
    <inertial>
      <origin
        xyz="0.000534 -0.007296 -0.018083"
        rpy="0 0 0" />
      <mass
        value="1.021" />
      <inertia
        ixx="0.001805"
        ixy="0.000006"
        ixz="-0.000015"
        iyy="0.001421"
        iyz="0.000080"
        izz="0.001292" />
    </inertial>
    <visual>
      <origin
        xyz="0 0 0"
        rpy="0 0 0" />
      <geometry>
        <mesh
          filename="7_dofs_arms_with_jaw/Hip_Pitch_Left.STL" />
      </geometry>
      <material
        name="">
        <color
          rgba="0.76 0.76 0.76 0.2" />
      </material>
    </visual>
    <collision>
      <origin
        xyz="0 0 0"
        rpy="0 0 0" />
      <geometry>
        <mesh
          filename="7_dofs_arms_with_jaw/Hip_Pitch_Left.STL" />
      </geometry>
    </collision>
  </link>
  <joint
    name="Left_Hip_Pitch"
    type="revolute">
    <origin
      xyz="0 0.106 0"
      rpy="0 0 0" />
    <parent
      link="Waist" />
    <child
      link="Hip_Pitch_Left" />
    <axis
      xyz="0 1 0" />
    <limit
      lower="0"
      upper="0"
      effort="0"
      velocity="0" />
  </joint>
  <link
    name="Hip_Roll_Left">
    <inertial>
      <origin
        xyz="0.001101 0.000024 -0.053750"
        rpy="0 0 0" />
      <mass
        value="0.385" />
      <inertia
        ixx="0.001517"
        ixy="0.000000"
        ixz="0.000017"
        iyy="0.001743"
        iyz="0.000000"
        izz="0.000515" />
    </inertial>
    <visual>
      <origin
        xyz="0 0 0"
        rpy="0 0 0" />
      <geometry>
        <mesh
          filename="7_dofs_arms_with_jaw/Hip_Roll_Left.STL" />
      </geometry>
      <material
        name="">
        <color
          rgba="0.4 0.4 0.4 0.3" />
      </material>
    </visual>
    <collision>
      <origin
        xyz="0 0 0"
        rpy="0 0 0" />
      <geometry>
        <mesh
          filename="7_dofs_arms_with_jaw/Hip_Roll_Left.STL" />
      </geometry>
    </collision>
  </link>
  <joint
    name="Left_Hip_Roll"
    type="revolute">
    <origin
      xyz="0 0 -0.02"
      rpy="0 0 0" />
    <parent
      link="Hip_Pitch_Left" />
    <child
      link="Hip_Roll_Left" />
    <axis
      xyz="1 0 0" />
    <limit
      lower="0"
      upper="0"
      effort="0"
      velocity="0" />
  </joint>
  <link
    name="Hip_Yaw_Left">
    <inertial>
      <origin
        xyz="-0.007233 0.000206 -0.089184"
        rpy="0 0 0" />
      <mass
        value="2.166" />
      <inertia
        ixx="0.025108"
        ixy="-0.000007"
        ixz="0.002094"
        iyy="0.025733"
        iyz="-0.000050"
        izz="0.002787" />
    </inertial>
    <visual>
      <origin
        xyz="0 0 0"
        rpy="0 0 0" />
      <geometry>
        <mesh
          filename="7_dofs_arms_with_jaw/Hip_Yaw_Left.STL" />
      </geometry>
      <material
        name="">
        <color
          rgba="0.4 0.4 0.4 0.3" />
      </material>
    </visual>
    <collision>
      <origin
        xyz="0 0 0"
        rpy="0 0 0" />
      <geometry>
        <mesh
          filename="7_dofs_arms_with_jaw/Hip_Yaw_Left.STL" />
      </geometry>
    </collision>
  </link>
  <joint
    name="Left_Hip_Yaw"
    type="revolute">
    <origin
      xyz="0 0 -0.081854"
      rpy="0 0 0" />
    <parent
      link="Hip_Roll_Left" />
    <child
      link="Hip_Yaw_Left" />
    <axis
      xyz="0 0 1" />
    <limit
      lower="0"
      upper="0"
      effort="0"
      velocity="0" />
  </joint>
  <link
    name="Shank_Left">
    <inertial>
      <origin
        xyz="-0.006012 0.000259 -0.124318"
        rpy="0 0 0" />
      <mass
        value="1.73" />
      <inertia
        ixx="0.034618"
        ixy="0.000011"
        ixz="0.001561"
        iyy="0.034539"
        iyz="0.000197"
        izz="0.001934" />
    </inertial>
    <visual>
      <origin
        xyz="0 0 0"
        rpy="0 0 0" />
      <geometry>
        <mesh
          filename="7_dofs_arms_with_jaw/Shank_Left.STL" />
      </geometry>
      <material
        name="">
        <color
          rgba="0.4 0.4 0.4 0.3" />
      </material>
    </visual>
    <collision>
      <origin
        xyz="0 0 0"
        rpy="0 0 0" />
      <geometry>
        <mesh
          filename="7_dofs_arms_with_jaw/Shank_Left.STL" />
      </geometry>
    </collision>
  </link>
  <joint
    name="Left_Knee_Pitch"
    type="revolute">
    <origin
      xyz="-0.014 0 -0.134"
      rpy="0 0 0" />
    <parent
      link="Hip_Yaw_Left" />
    <child
      link="Shank_Left" />
    <axis
      xyz="0 1 0" />
    <limit
      lower="0"
      upper="0"
      effort="0"
      velocity="0" />
  </joint>
  <link
    name="Ankle_Cross_Left">
    <inertial>
      <origin
        xyz="-0.003722 0.000000 -0.007981"
        rpy="0 0 0" />
      <mass
        value="0.073" />
      <inertia
        ixx="0.000012"
        ixy="0.000000"
        ixz="0.000003"
        iyy="0.000029"
        iyz="0.000000"
        izz="0.000025" />
    </inertial>
    <visual>
      <origin
        xyz="0 0 0"
        rpy="0 0 0" />
      <geometry>
        <mesh
          filename="7_dofs_arms_with_jaw/Ankle_Cross_Left.STL" />
      </geometry>
      <material
        name="">
        <color
          rgba="0.4 0.4 0.4 0.3" />
      </material>
    </visual>
    <collision>
      <origin
        xyz="0 0 0"
        rpy="0 0 0" />
      <geometry>
        <mesh
          filename="7_dofs_arms_with_jaw/Ankle_Cross_Left.STL" />
      </geometry>
    </collision>
  </link>
  <joint
    name="Left_Ankle_Pitch"
    type="revolute">
    <origin
      xyz="0 0 -0.28"
      rpy="0 0 0" />
    <parent
      link="Shank_Left" />
    <child
      link="Ankle_Cross_Left" />
    <axis
      xyz="0 1 0" />
    <limit
      lower="0"
      upper="0"
      effort="0"
      velocity="0" />
  </joint>
  <link
    name="left_foot_link">
    <inertial>
      <origin
        xyz="-0.000249 0.000000 -0.009140"
        rpy="0 0 0" />
      <mass
        value="0.685" />
      <inertia
        ixx="0.000738"
        ixy="0.000000"
        ixz="-0.000147"
        iyy="0.002385"
        iyz="0.000000"
        izz="0.002671" />
    </inertial>
    <visual>
      <origin
        xyz="0 0 0"
        rpy="0 0 0" />
      <geometry>
        <mesh
          filename="7_dofs_arms_with_jaw/left_foot_link.STL" />
      </geometry>
      <material
        name="">
        <color
          rgba="0.4 0.4 0.4 0.3" />
      </material>
    </visual>
    <collision>
      <origin
        xyz="0 0 0"
        rpy="0 0 0" />
      <geometry>
        <mesh
          filename="7_dofs_arms_with_jaw/left_foot_link.STL" />
      </geometry>
    </collision>
  </link>
  <joint
    name="Left_Ankle_Roll"
    type="revolute">
    <origin
      xyz="0 0.00025 -0.012"
      rpy="0 0 0" />
    <parent
      link="Ankle_Cross_Left" />
    <child
      link="left_foot_link" />
    <axis
      xyz="1 0 0" />
    <limit
      lower="0"
      upper="0"
      effort="0"
      velocity="0" />
  </joint>
  
  <link
    name="Hip_Pitch_Right">
    <inertial>
      <origin
        xyz="0.000534 0.007514 -0.018082"
        rpy="0 0 0" />
      <mass
        value="1.021" />
      <inertia
        ixx="0.001805"
        ixy="-0.000008"
        ixz="-0.000015"
        iyy="0.001421"
        iyz="-0.000085"
        izz="0.001292" />
    </inertial>
    <visual>
      <origin
        xyz="0 0 0"
        rpy="0 0 0" />
      <geometry>
        <mesh
          filename="7_dofs_arms_with_jaw/Hip_Pitch_Right.STL" />
      </geometry>
      <material
        name="">
        <color
          rgba="0.76 0.76 0.76 0.2" />
      </material>
    </visual>
    <collision>
      <origin
        xyz="0 0 0"
        rpy="0 0 0" />
      <geometry>
        <mesh
          filename="7_dofs_arms_with_jaw/Hip_Pitch_Right.STL" />
      </geometry>
    </collision>
  </link>
  <joint
    name="Right_Hip_Pitch"
    type="revolute">
    <origin
      xyz="0 -0.106 0"
      rpy="0 0 0" />
    <parent
      link="Waist" />
    <child
      link="Hip_Pitch_Right" />
    <axis
      xyz="0 1 0" />
    <limit
      lower="0"
      upper="0"
      effort="0"
      velocity="0" />
  </joint>
  <link
    name="Hip_Roll_Right">
    <inertial>
      <origin
        xyz="0.001099 0.000024 -0.053748"
        rpy="0 0 0" />
      <mass
        value="0.385" />
      <inertia
        ixx="0.001517"
        ixy="0.000000"
        ixz="0.000017"
        iyy="0.001743"
        iyz="0.000000"
        izz="0.000515" />
    </inertial>
    <visual>
      <origin
        xyz="0 0 0"
        rpy="0 0 0" />
      <geometry>
        <mesh
          filename="7_dofs_arms_with_jaw/Hip_Roll_Right.STL" />
      </geometry>
      <material
        name="">
        <color
          rgba="0.4 0.4 0.4 0.3" />
      </material>
    </visual>
    <collision>
      <origin
        xyz="0 0 0"
        rpy="0 0 0" />
      <geometry>
        <mesh
          filename="7_dofs_arms_with_jaw/Hip_Roll_Right.STL" />
      </geometry>
    </collision>
  </link>
  <joint
    name="Right_Hip_Roll"
    type="revolute">
    <origin
      xyz="0 0 -0.02"
      rpy="0 0 0" />
    <parent
      link="Hip_Pitch_Right" />
    <child
      link="Hip_Roll_Right" />
    <axis
      xyz="1 0 0" />
    <limit
      lower="0"
      upper="0"
      effort="0"
      velocity="0" />
  </joint>
  <link
    name="Hip_Yaw_Right">
    <inertial>
      <origin
        xyz="-0.007191 -0.000149 -0.089220"
        rpy="0 0 0" />
      <mass
        value="2.17" />
      <inertia
        ixx="0.025137"
        ixy="0.000006"
        ixz="0.002086"
        iyy="0.025762"
        iyz="0.000044"
        izz="0.002787" />
    </inertial>
    <visual>
      <origin
        xyz="0 0 0"
        rpy="0 0 0" />
      <geometry>
        <mesh
          filename="7_dofs_arms_with_jaw/Hip_Yaw_Right.STL" />
      </geometry>
      <material
        name="">
        <color
          rgba="0.4 0.4 0.4 0.3" />
      </material>
    </visual>
    <collision>
      <origin
        xyz="0 0 0"
        rpy="0 0 0" />
      <geometry>
        <mesh
          filename="7_dofs_arms_with_jaw/Hip_Yaw_Right.STL" />
      </geometry>
    </collision>
  </link>
  <joint
    name="Right_Hip_Yaw"
    type="revolute">
    <origin
      xyz="0 0 -0.081854"
      rpy="0 0 0" />
    <parent
      link="Hip_Roll_Right" />
    <child
      link="Hip_Yaw_Right" />
    <axis
      xyz="0 0 1" />
    <limit
      lower="0"
      upper="0"
      effort="0"
      velocity="0" />
  </joint>
  <link
    name="Shank_Right">
    <inertial>
      <origin
        xyz="-0.005741 -0.000541 -0.122602"
        rpy="0 0 0" />
      <mass
        value="1.79" />
      <inertia
        ixx="0.035098"
        ixy="-0.000009"
        ixz="0.001554"
        iyy="0.034958"
        iyz="-0.000086"
        izz="0.002039" />
    </inertial>
    <visual>
      <origin
        xyz="0 0 0"
        rpy="0 0 0" />
      <geometry>
        <mesh
          filename="7_dofs_arms_with_jaw/Shank_Right.STL" />
      </geometry>
      <material
        name="">
        <color
          rgba="0.4 0.4 0.4 0.3" />
      </material>
    </visual>
    <collision>
      <origin
        xyz="0 0 0"
        rpy="0 0 0" />
      <geometry>
        <mesh
          filename="7_dofs_arms_with_jaw/Shank_Right.STL" />
      </geometry>
    </collision>
  </link>
  <joint
    name="Right_Knee_Pitch"
    type="revolute">
    <origin
      xyz="-0.014 0 -0.134"
      rpy="0 0 0" />
    <parent
      link="Hip_Yaw_Right" />
    <child
      link="Shank_Right" />
    <axis
      xyz="0 1 0" />
    <limit
      lower="0"
      upper="0"
      effort="0"
      velocity="0" />
  </joint>
  <link
    name="Ankle_Cross_Right">
    <inertial>
      <origin
        xyz="-0.003722 0.000000 -0.007981"
        rpy="0 0 0" />
      <mass
        value="0.073" />
      <inertia
        ixx="0.000012"
        ixy="0.000000"
        ixz="0.000003"
        iyy="0.000029"
        iyz="0.000000"
        izz="0.000025" />
    </inertial>
    <visual>
      <origin
        xyz="0 0 0"
        rpy="0 0 0" />
      <geometry>
        <mesh
          filename="7_dofs_arms_with_jaw/Ankle_Cross_Right.STL" />
      </geometry>
      <material
        name="">
        <color
          rgba="0.4 0.4 0.4 0.3" />
      </material>
    </visual>
    <collision>
      <origin
        xyz="0 0 0"
        rpy="0 0 0" />
      <geometry>
        <mesh
          filename="7_dofs_arms_with_jaw/Ankle_Cross_Right.STL" />
      </geometry>
    </collision>
  </link>
  <joint
    name="Right_Ankle_Pitch"
    type="revolute">
    <origin
      xyz="0 0 -0.28"
      rpy="0 0 0" />
    <parent
      link="Shank_Right" />
    <child
      link="Ankle_Cross_Right" />
    <axis
      xyz="0 1 0" />
    <limit
      lower="0"
      upper="0"
      effort="0"
      velocity="0" />
  </joint>
  <link
    name="right_foot_link">
    <inertial>
      <origin
        xyz="-0.000248 0.000000 -0.009140"
        rpy="0 0 0" />
      <mass
        value="0.685" />
      <inertia
        ixx="0.000738"
        ixy="0.000000"
        ixz="-0.000147"
        iyy="0.002385"
        iyz="0.000000"
        izz="0.002671" />
    </inertial>
    <visual>
      <origin
        xyz="0 0 0"
        rpy="0 0 0" />
      <geometry>
        <mesh
          filename="7_dofs_arms_with_jaw/right_foot_link.STL" />
      </geometry>
      <material
        name="">
        <color
          rgba="0.4 0.4 0.4 0.3" />
      </material>
    </visual>
    <collision>
      <origin
        xyz="0 0 0"
        rpy="0 0 0" />
      <geometry>
        <mesh
          filename="7_dofs_arms_with_jaw/right_foot_link.STL" />
      </geometry>
    </collision>
  </link>
  <joint
    name="Right_Ankle_Roll"
    type="revolute">
    <origin
      xyz="0 -0.00025 -0.012"
      rpy="0 0 0" />
    <parent
      link="Ankle_Cross_Right" />
    <child
      link="right_foot_link" />
    <axis
      xyz="1 0 0" />
    <limit
      lower="0"
      upper="0"
      effort="0"
      velocity="0" />
  </joint>
</robot>